Workbook

Sheet 1. Yönetici Özeti
B2: DORUK SAĞLIK GRUBU — META (Instagram/Facebook) REKLAM ANALİZİ
B3: Rapor Dönemi: 23 Haziran 2026 – 22 Temmuz 2026 (30 günlük pencere · 26 aktif gün)
B5: ANA GÖSTERGELER
B6: Toplam Harcama | E6: =SUM('Ham Veri (Kategorili)'!G2:G763)
B7: Günlük Ort. (26 aktif gün) | E7: =SUM('Ham Veri (Kategorili)'!G2:G763)/26
B8: Günlük Ort. (30 gün pencere) | E8: =SUM('Ham Veri (Kategorili)'!G2:G763)/30
B9: Toplam Kampanya Sayısı | E9: 58
B10: Sayfa Sayısı | E10: 6
B12: ANA KATEGORİ DAĞILIMI (Sayfa Tipine Göre)
B13: Ana Kategori | C13: Harcama | D13: Pay % | E13: Günlük Ort. (30g)
B14: Hastane (Kurumsal) | C14: =SUMIFS('Ham Veri (Kategorili)'!$G$2:$G$763,'Ham Veri (Kategorili)'!$D$2:$D$763,"Hastane (Kurumsal)") | D14: =SUMIFS('Ham Veri (Kategorili)'!$G$2:$G$763,'Ham Veri (Kategorili)'!$D$2:$D$763,"Hastane (Kurumsal)")/SUM('Ham Veri (Kategorili)'!$G$2:$G$763) | E14: =SUMIFS('Ham Veri (Kategorili)'!$G$2:$G$763,'Ham Veri (Kategorili)'!$D$2:$D$763,"Hastane (Kurumsal)")/30
B15: Estetik Marka | C15: =SUMIFS('Ham Veri (Kategorili)'!$G$2:$G$763,'Ham Veri (Kategorili)'!$D$2:$D$763,"Estetik Marka") | D15: =SUMIFS('Ham Veri (Kategorili)'!$G$2:$G$763,'Ham Veri (Kategorili)'!$D$2:$D$763,"Estetik Marka")/SUM('Ham Veri (Kategorili)'!$G$2:$G$763) | E15: =SUMIFS('Ham Veri (Kategorili)'!$G$2:$G$763,'Ham Veri (Kategorili)'!$D$2:$D$763,"Estetik Marka")/30
B16: Doktor Sayfaları | C16: =SUMIFS('Ham Veri (Kategorili)'!$G$2:$G$763,'Ham Veri (Kategorili)'!$D$2:$D$763,"Doktor Sayfaları") | D16: =SUMIFS('Ham Veri (Kategorili)'!$G$2:$G$763,'Ham Veri (Kategorili)'!$D$2:$D$763,"Doktor Sayfaları")/SUM('Ham Veri (Kategorili)'!$G$2:$G$763) | E16: =SUMIFS('Ham Veri (Kategorili)'!$G$2:$G$763,'Ham Veri (Kategorili)'!$D$2:$D$763,"Doktor Sayfaları")/30
B17: TOPLAM | C17: =SUM('Ham Veri (Kategorili)'!$G$2:$G$763) | D17: =SUM('Ham Veri (Kategorili)'!$G$2:$G$763)/SUM('Ham Veri (Kategorili)'!$G$2:$G$763) | E17: =SUM('Ham Veri (Kategorili)'!$G$2:$G$763)/30
B19: KAMPANYA AMACI DAĞILIMI (Ne İçin Harcandı?)
B20: Kampanya Amacı | C20: Harcama | D20: Pay % | E20: Günlük Ort. (30g)
B21: Lead Toplama (Form) | C21: =SUMIFS('Ham Veri (Kategorili)'!$G$2:$G$763,'Ham Veri (Kategorili)'!$E$2:$E$763,"Lead Toplama (Form)") | D21: =SUMIFS('Ham Veri (Kategorili)'!$G$2:$G$763,'Ham Veri (Kategorili)'!$E$2:$E$763,"Lead Toplama (Form)")/SUM('Ham Veri (Kategorili)'!$G$2:$G$763) | E21: =SUMIFS('Ham Veri (Kategorili)'!$G$2:$G$763,'Ham Veri (Kategorili)'!$E$2:$E$763,"Lead Toplama (Form)")/30
B22: Instagram Öne Çıkarma | C22: =SUMIFS('Ham Veri (Kategorili)'!$G$2:$G$763,'Ham Veri (Kategorili)'!$E$2:$E$763,"Instagram Öne Çıkarma") | D22: =SUMIFS('Ham Veri (Kategorili)'!$G$2:$G$763,'Ham Veri (Kategorili)'!$E$2:$E$763,"Instagram Öne Çıkarma")/SUM('Ham Veri (Kategorili)'!$G$2:$G$763) | E22: =SUMIFS('Ham Veri (Kategorili)'!$G$2:$G$763,'Ham Veri (Kategorili)'!$E$2:$E$763,"Instagram Öne Çıkarma")/30
B23: Marka Bilinirliği (Erişim) | C23: =SUMIFS('Ham Veri (Kategorili)'!$G$2:$G$763,'Ham Veri (Kategorili)'!$E$2:$E$763,"Marka Bilinirliği (Erişim)") | D23: =SUMIFS('Ham Veri (Kategorili)'!$G$2:$G$763,'Ham Veri (Kategorili)'!$E$2:$E$763,"Marka Bilinirliği (Erişim)")/SUM('Ham Veri (Kategorili)'!$G$2:$G$763) | E23: =SUMIFS('Ham Veri (Kategorili)'!$G$2:$G$763,'Ham Veri (Kategorili)'!$E$2:$E$763,"Marka Bilinirliği (Erişim)")/30
B26: YORUM / TESPİTLER
B27: • Harcamanın %84,5'i Hastane (Kurumsal) sayfasından; kalan doktor ve estetik marka sayfalarından yapılıyor.
B28: • Amaç bazında en büyük kalem Lead Toplama (%51,2) — asıl hedef hasta/başvuru kaydı toplamak.
B29: • Instagram Öne Çıkarmalar toplam bütçenin %27'si; bunun içinde Doruk Hastaneleri %64,6, Doktorlar %22,8, Estetik %12,6.
B30: • Marka Bilinirliği (Erişim) %21,8 — en büyük parça "Doktor - Bilinirlik" kampanyaları (Nilüfer + Yıldırım).
B31: • Detaylı kırılımlar için "2. Kategori Analizi", kampanya bazında "3. Kampanya Detayı",
B32: günlük 60.000 TL senaryosu için "4. 60 Bin TL Dağıtımı" sekmesine bakınız.

Sheet 2. Kategori Analizi
B2: KATEGORİ ANALİZİ — Titiz Kırılım
B4: A) ANA KATEGORİ — Sayfa Tipi (Hastane / Marka / Doktor)
B5: Kategori | C5: Harcama (TL) | D5: Pay % | E5: Günlük Ort. (30g) | F5: Aktif Gün Ort.
B6: Hastane (Kurumsal) | C6: =SUMIFS('Ham Veri (Kategorili)'!$G$2:$G$763,'Ham Veri (Kategorili)'!$D$2:$D$763,"Hastane (Kurumsal)") | D6: =SUMIFS('Ham Veri (Kategorili)'!$G$2:$G$763,'Ham Veri (Kategorili)'!$D$2:$D$763,"Hastane (Kurumsal)")/SUM('Ham Veri (Kategorili)'!$G$2:$G$763) | E6: =SUMIFS('Ham Veri (Kategorili)'!$G$2:$G$763,'Ham Veri (Kategorili)'!$D$2:$D$763,"Hastane (Kurumsal)")/30 | F6: =SUMIFS('Ham Veri (Kategorili)'!$G$2:$G$763,'Ham Veri (Kategorili)'!$D$2:$D$763,"Hastane (Kurumsal)")/26
B7: Estetik Marka | C7: =SUMIFS('Ham Veri (Kategorili)'!$G$2:$G$763,'Ham Veri (Kategorili)'!$D$2:$D$763,"Estetik Marka") | D7: =SUMIFS('Ham Veri (Kategorili)'!$G$2:$G$763,'Ham Veri (Kategorili)'!$D$2:$D$763,"Estetik Marka")/SUM('Ham Veri (Kategorili)'!$G$2:$G$763) | E7: =SUMIFS('Ham Veri (Kategorili)'!$G$2:$G$763,'Ham Veri (Kategorili)'!$D$2:$D$763,"Estetik Marka")/30 | F7: =SUMIFS('Ham Veri (Kategorili)'!$G$2:$G$763,'Ham Veri (Kategorili)'!$D$2:$D$763,"Estetik Marka")/26
B8: Doktor Sayfaları | C8: =SUMIFS('Ham Veri (Kategorili)'!$G$2:$G$763,'Ham Veri (Kategorili)'!$D$2:$D$763,"Doktor Sayfaları") | D8: =SUMIFS('Ham Veri (Kategorili)'!$G$2:$G$763,'Ham Veri (Kategorili)'!$D$2:$D$763,"Doktor Sayfaları")/SUM('Ham Veri (Kategorili)'!$G$2:$G$763) | E8: =SUMIFS('Ham Veri (Kategorili)'!$G$2:$G$763,'Ham Veri (Kategorili)'!$D$2:$D$763,"Doktor Sayfaları")/30 | F8: =SUMIFS('Ham Veri (Kategorili)'!$G$2:$G$763,'Ham Veri (Kategorili)'!$D$2:$D$763,"Doktor Sayfaları")/26
B9: TOPLAM | C9: =SUM(C6:C8) | D9: =SUM(D6:D8) | E9: =SUM(E6:E8) | F9: =SUM(F6:F8)
B11: B) KAMPANYA AMACI — Ne İçin? (Lead / Öne Çıkarma / Bilinirlik)
B12: Kategori | C12: Harcama (TL) | D12: Pay % | E12: Günlük Ort. (30g) | F12: Aktif Gün Ort.
B13: Lead Toplama (Form) | C13: =SUMIFS('Ham Veri (Kategorili)'!$G$2:$G$763,'Ham Veri (Kategorili)'!$E$2:$E$763,"Lead Toplama (Form)") | D13: =SUMIFS('Ham Veri (Kategorili)'!$G$2:$G$763,'Ham Veri (Kategorili)'!$E$2:$E$763,"Lead Toplama (Form)")/SUM('Ham Veri (Kategorili)'!$G$2:$G$763) | E13: =SUMIFS('Ham Veri (Kategorili)'!$G$2:$G$763,'Ham Veri (Kategorili)'!$E$2:$E$763,"Lead Toplama (Form)")/30 | F13: =SUMIFS('Ham Veri (Kategorili)'!$G$2:$G$763,'Ham Veri (Kategorili)'!$E$2:$E$763,"Lead Toplama (Form)")/26
B14: Instagram Öne Çıkarma | C14: =SUMIFS('Ham Veri (Kategorili)'!$G$2:$G$763,'Ham Veri (Kategorili)'!$E$2:$E$763,"Instagram Öne Çıkarma") | D14: =SUMIFS('Ham Veri (Kategorili)'!$G$2:$G$763,'Ham Veri (Kategorili)'!$E$2:$E$763,"Instagram Öne Çıkarma")/SUM('Ham Veri (Kategorili)'!$G$2:$G$763) | E14: =SUMIFS('Ham Veri (Kategorili)'!$G$2:$G$763,'Ham Veri (Kategorili)'!$E$2:$E$763,"Instagram Öne Çıkarma")/30 | F14: =SUMIFS('Ham Veri (Kategorili)'!$G$2:$G$763,'Ham Veri (Kategorili)'!$E$2:$E$763,"Instagram Öne Çıkarma")/26
B15: Marka Bilinirliği (Erişim) | C15: =SUMIFS('Ham Veri (Kategorili)'!$G$2:$G$763,'Ham Veri (Kategorili)'!$E$2:$E$763,"Marka Bilinirliği (Erişim)") | D15: =SUMIFS('Ham Veri (Kategorili)'!$G$2:$G$763,'Ham Veri (Kategorili)'!$E$2:$E$763,"Marka Bilinirliği (Erişim)")/SUM('Ham Veri (Kategorili)'!$G$2:$G$763) | E15: =SUMIFS('Ham Veri (Kategorili)'!$G$2:$G$763,'Ham Veri (Kategorili)'!$E$2:$E$763,"Marka Bilinirliği (Erişim)")/30 | F15: =SUMIFS('Ham Veri (Kategorili)'!$G$2:$G$763,'Ham Veri (Kategorili)'!$E$2:$E$763,"Marka Bilinirliği (Erişim)")/26
B16: TOPLAM | C16: =SUM(C13:C15) | D16: =SUM(D13:D15) | E16: =SUM(E13:E15) | F16: =SUM(F13:F15)
B18: C) INSTAGRAM ÖNE ÇIKARMA — Alt Kırılım (Hastane vs Doktor vs Estetik)
B19: Kategori | C19: Harcama (TL) | D19: Pay % | E19: Günlük Ort. (30g) | F19: Aktif Gün Ort.
B20: Öne Çıkarma - Doruk Hastaneleri | C20: =SUMIFS('Ham Veri (Kategorili)'!$G$2:$G$763,'Ham Veri (Kategorili)'!$F$2:$F$763,"Öne Çıkarma - Doruk Hastaneleri") | D20: =SUMIFS('Ham Veri (Kategorili)'!$G$2:$G$763,'Ham Veri (Kategorili)'!$F$2:$F$763,"Öne Çıkarma - Doruk Hastaneleri")/SUM('Ham Veri (Kategorili)'!$G$2:$G$763) | E20: =SUMIFS('Ham Veri (Kategorili)'!$G$2:$G$763,'Ham Veri (Kategorili)'!$F$2:$F$763,"Öne Çıkarma - Doruk Hastaneleri")/30 | F20: =SUMIFS('Ham Veri (Kategorili)'!$G$2:$G$763,'Ham Veri (Kategorili)'!$F$2:$F$763,"Öne Çıkarma - Doruk Hastaneleri")/26
B21: Öne Çıkarma - Doktor | C21: =SUMIFS('Ham Veri (Kategorili)'!$G$2:$G$763,'Ham Veri (Kategorili)'!$F$2:$F$763,"Öne Çıkarma - Doktor") | D21: =SUMIFS('Ham Veri (Kategorili)'!$G$2:$G$763,'Ham Veri (Kategorili)'!$F$2:$F$763,"Öne Çıkarma - Doktor")/SUM('Ham Veri (Kategorili)'!$G$2:$G$763) | E21: =SUMIFS('Ham Veri (Kategorili)'!$G$2:$G$763,'Ham Veri (Kategorili)'!$F$2:$F$763,"Öne Çıkarma - Doktor")/30 | F21: =SUMIFS('Ham Veri (Kategorili)'!$G$2:$G$763,'Ham Veri (Kategorili)'!$F$2:$F$763,"Öne Çıkarma - Doktor")/26
B22: Öne Çıkarma - Doruk Estetik | C22: =SUMIFS('Ham Veri (Kategorili)'!$G$2:$G$763,'Ham Veri (Kategorili)'!$F$2:$F$763,"Öne Çıkarma - Doruk Estetik") | D22: =SUMIFS('Ham Veri (Kategorili)'!$G$2:$G$763,'Ham Veri (Kategorili)'!$F$2:$F$763,"Öne Çıkarma - Doruk Estetik")/SUM('Ham Veri (Kategorili)'!$G$2:$G$763) | E22: =SUMIFS('Ham Veri (Kategorili)'!$G$2:$G$763,'Ham Veri (Kategorili)'!$F$2:$F$763,"Öne Çıkarma - Doruk Estetik")/30 | F22: =SUMIFS('Ham Veri (Kategorili)'!$G$2:$G$763,'Ham Veri (Kategorili)'!$F$2:$F$763,"Öne Çıkarma - Doruk Estetik")/26
B23: TOPLAM | C23: =SUM(C20:C22) | D23: =SUM(D20:D22) | E23: =SUM(E20:E22) | F23: =SUM(F20:F22)
B25: D) LEAD TOPLAMA — Konu Bazında Alt Kırılım
B26: Kategori | C26: Harcama (TL) | D26: Pay % | E26: Günlük Ort. (30g) | F26: Aktif Gün Ort.
B27: Lead - Kadın Doğum/Gebe/FTR | C27: =SUMIFS('Ham Veri (Kategorili)'!$G$2:$G$763,'Ham Veri (Kategorili)'!$F$2:$F$763,"Lead - Kadın Doğum/Gebe/FTR") | D27: =SUMIFS('Ham Veri (Kategorili)'!$G$2:$G$763,'Ham Veri (Kategorili)'!$F$2:$F$763,"Lead - Kadın Doğum/Gebe/FTR")/SUM('Ham Veri (Kategorili)'!$G$2:$G$763) | E27: =SUMIFS('Ham Veri (Kategorili)'!$G$2:$G$763,'Ham Veri (Kategorili)'!$F$2:$F$763,"Lead - Kadın Doğum/Gebe/FTR")/30 | F27: =SUMIFS('Ham Veri (Kategorili)'!$G$2:$G$763,'Ham Veri (Kategorili)'!$F$2:$F$763,"Lead - Kadın Doğum/Gebe/FTR")/26
B28: Lead - Estetik/Plastik/Saç | C28: =SUMIFS('Ham Veri (Kategorili)'!$G$2:$G$763,'Ham Veri (Kategorili)'!$F$2:$F$763,"Lead - Estetik/Plastik/Saç") | D28: =SUMIFS('Ham Veri (Kategorili)'!$G$2:$G$763,'Ham Veri (Kategorili)'!$F$2:$F$763,"Lead - Estetik/Plastik/Saç")/SUM('Ham Veri (Kategorili)'!$G$2:$G$763) | E28: =SUMIFS('Ham Veri (Kategorili)'!$G$2:$G$763,'Ham Veri (Kategorili)'!$F$2:$F$763,"Lead - Estetik/Plastik/Saç")/30 | F28: =SUMIFS('Ham Veri (Kategorili)'!$G$2:$G$763,'Ham Veri (Kategorili)'!$F$2:$F$763,"Lead - Estetik/Plastik/Saç")/26
B29: Lead - Check-up/Tarama | C29: =SUMIFS('Ham Veri (Kategorili)'!$G$2:$G$763,'Ham Veri (Kategorili)'!$F$2:$F$763,"Lead - Check-up/Tarama") | D29: =SUMIFS('Ham Veri (Kategorili)'!$G$2:$G$763,'Ham Veri (Kategorili)'!$F$2:$F$763,"Lead - Check-up/Tarama")/SUM('Ham Veri (Kategorili)'!$G$2:$G$763) | E29: =SUMIFS('Ham Veri (Kategorili)'!$G$2:$G$763,'Ham Veri (Kategorili)'!$F$2:$F$763,"Lead - Check-up/Tarama")/30 | F29: =SUMIFS('Ham Veri (Kategorili)'!$G$2:$G$763,'Ham Veri (Kategorili)'!$F$2:$F$763,"Lead - Check-up/Tarama")/26
B30: Lead - İK/İş Başvurusu | C30: =SUMIFS('Ham Veri (Kategorili)'!$G$2:$G$763,'Ham Veri (Kategorili)'!$F$2:$F$763,"Lead - İK/İş Başvurusu") | D30: =SUMIFS('Ham Veri (Kategorili)'!$G$2:$G$763,'Ham Veri (Kategorili)'!$F$2:$F$763,"Lead - İK/İş Başvurusu")/SUM('Ham Veri (Kategorili)'!$G$2:$G$763) | E30: =SUMIFS('Ham Veri (Kategorili)'!$G$2:$G$763,'Ham Veri (Kategorili)'!$F$2:$F$763,"Lead - İK/İş Başvurusu")/30 | F30: =SUMIFS('Ham Veri (Kategorili)'!$G$2:$G$763,'Ham Veri (Kategorili)'!$F$2:$F$763,"Lead - İK/İş Başvurusu")/26
B31: TOPLAM | C31: =SUM(C27:C30) | D31: =SUM(D27:D30) | E31: =SUM(E27:E30) | F31: =SUM(F27:F30)
B33: E) MARKA BİLİNİRLİĞİ — Alt Kırılım
B34: Kategori | C34: Harcama (TL) | D34: Pay % | E34: Günlük Ort. (30g) | F34: Aktif Gün Ort.
B35: Bilinirlik - Doktor Tanıtım | C35: =SUMIFS('Ham Veri (Kategorili)'!$G$2:$G$763,'Ham Veri (Kategorili)'!$F$2:$F$763,"Bilinirlik - Doktor Tanıtım") | D35: =SUMIFS('Ham Veri (Kategorili)'!$G$2:$G$763,'Ham Veri (Kategorili)'!$F$2:$F$763,"Bilinirlik - Doktor Tanıtım")/SUM('Ham Veri (Kategorili)'!$G$2:$G$763) | E35: =SUMIFS('Ham Veri (Kategorili)'!$G$2:$G$763,'Ham Veri (Kategorili)'!$F$2:$F$763,"Bilinirlik - Doktor Tanıtım")/30 | F35: =SUMIFS('Ham Veri (Kategorili)'!$G$2:$G$763,'Ham Veri (Kategorili)'!$F$2:$F$763,"Bilinirlik - Doktor Tanıtım")/26
B36: Bilinirlik - Kurumsal (ÖSS-TSS) | C36: =SUMIFS('Ham Veri (Kategorili)'!$G$2:$G$763,'Ham Veri (Kategorili)'!$F$2:$F$763,"Bilinirlik - Kurumsal (ÖSS-TSS)") | D36: =SUMIFS('Ham Veri (Kategorili)'!$G$2:$G$763,'Ham Veri (Kategorili)'!$F$2:$F$763,"Bilinirlik - Kurumsal (ÖSS-TSS)")/SUM('Ham Veri (Kategorili)'!$G$2:$G$763) | E36: =SUMIFS('Ham Veri (Kategorili)'!$G$2:$G$763,'Ham Veri (Kategorili)'!$F$2:$F$763,"Bilinirlik - Kurumsal (ÖSS-TSS)")/30 | F36: =SUMIFS('Ham Veri (Kategorili)'!$G$2:$G$763,'Ham Veri (Kategorili)'!$F$2:$F$763,"Bilinirlik - Kurumsal (ÖSS-TSS)")/26
B37: Bilinirlik - Gebe/Doğum | C37: =SUMIFS('Ham Veri (Kategorili)'!$G$2:$G$763,'Ham Veri (Kategorili)'!$F$2:$F$763,"Bilinirlik - Gebe/Doğum") | D37: =SUMIFS('Ham Veri (Kategorili)'!$G$2:$G$763,'Ham Veri (Kategorili)'!$F$2:$F$763,"Bilinirlik - Gebe/Doğum")/SUM('Ham Veri (Kategorili)'!$G$2:$G$763) | E37: =SUMIFS('Ham Veri (Kategorili)'!$G$2:$G$763,'Ham Veri (Kategorili)'!$F$2:$F$763,"Bilinirlik - Gebe/Doğum")/30 | F37: =SUMIFS('Ham Veri (Kategorili)'!$G$2:$G$763,'Ham Veri (Kategorili)'!$F$2:$F$763,"Bilinirlik - Gebe/Doğum")/26
B38: TOPLAM | C38: =SUM(C35:C37) | D38: =SUM(D35:D37) | E38: =SUM(E35:E37) | F38: =SUM(F35:F37)

Sheet 3. Kampanya Detayı
A1: Ana Kategori | B1: Amaç | C1: Alt Kategori | D1: Sayfa | E1: Kampanya | F1: Harcama (TL) | G1: Pay % | H1: Aktif Gün | I1: Günlük Ort. | J1: Toplam Sonuç
A2: Hastane (Kurumsal) | B2: Lead Toplama (Form) | C2: Lead - Kadın Doğum/Gebe/FTR | D2: Doruk Hastaneleri | E2: Gebe-Doğum Form Kampanyası | F2: 173818.84 | G2: =F2/SUM($F$2:$F$59) | H2: 26 | I2: =F2/H2 | J2: 545
A3: Hastane (Kurumsal) | B3: Marka Bilinirliği (Erişim) | C3: Bilinirlik - Doktor Tanıtım | D3: Doruk Hastaneleri | E3: Doktor - Bilinirlik Kampanyası - Nilüfer | F3: 132923.79 | G3: =F3/SUM($F$2:$F$59) | H3: 26 | I3: =F3/H3 | J3: 11264434
A4: Hastane (Kurumsal) | B4: Lead Toplama (Form) | C4: Lead - Kadın Doğum/Gebe/FTR | D4: Doruk Hastaneleri | E4: FTR Yatılı - lead | F4: 97495.28 | G4: =F4/SUM($F$2:$F$59) | H4: 26 | I4: =F4/H4 | J4: 144
A5: Hastane (Kurumsal) | B5: Instagram Öne Çıkarma | C5: Öne Çıkarma - Doruk Hastaneleri | D5: Doruk Hastaneleri | E5: Instagram gönderisi: Bir sezon boyunca ortaya... | F5: 93455.9 | G5: =F5/SUM($F$2:$F$59) | H5: 26 | I5: =F5/H5 | J5: 19050
A6: Estetik Marka | B6: Lead Toplama (Form) | C6: Lead - Estetik/Plastik/Saç | D6: Doruk Estetik & Saç Ekimi | E6: ABO / Medikal Estetik lead / 16.04.2026 | F6: 60093.26 | G6: =F6/SUM($F$2:$F$59) | H6: 26 | I6: =F6/H6 | J6: 518
A7: Hastane (Kurumsal) | B7: Instagram Öne Çıkarma | C7: Öne Çıkarma - Doruk Hastaneleri | D7: Doruk Hastaneleri | E7: Instagram gönderisi: Doruk Sağlık Grubu olarak,... | F7: 46303.32 | G7: =F7/SUM($F$2:$F$59) | H7: 19 | I7: =F7/H7 | J7: 10830
A8: Hastane (Kurumsal) | B8: Marka Bilinirliği (Erişim) | C8: Bilinirlik - Kurumsal (ÖSS-TSS) | D8: Doruk Hastaneleri | E8: ÖSS-TSS - marka bilinirliği | F8: 46163.29 | G8: =F8/SUM($F$2:$F$59) | H8: 26 | I8: =F8/H8 | J8: 3127678
A9: Hastane (Kurumsal) | B9: Lead Toplama (Form) | C9: Lead - İK/İş Başvurusu | D9: Doruk Hastaneleri | E9: Hemşire İş Başvuru - lead | F9: 24219.27 | G9: =F9/SUM($F$2:$F$59) | H9: 26 | I9: =F9/H9 | J9: 65
A10: Hastane (Kurumsal) | B10: Lead Toplama (Form) | C10: Lead - İK/İş Başvurusu | D10: Doruk Hastaneleri | E10: Uzman Hekim Başvuru | F10: 23972.09 | G10: =F10/SUM($F$2:$F$59) | H10: 26 | I10: =F10/H10 | J10: 118
A11: Hastane (Kurumsal) | B11: Marka Bilinirliği (Erişim) | C11: Bilinirlik - Gebe/Doğum | D11: Doruk Hastaneleri | E11: Gebe-Doğum Bilinirlik | F11: 23489.82 | G11: =F11/SUM($F$2:$F$59) | H11: 26 | I11: =F11/H11 | J11: 2222938
A12: Hastane (Kurumsal) | B12: Lead Toplama (Form) | C12: Lead - Check-up/Tarama | D12: Doruk Hastaneleri | E12: Checkup - genel - lead | F12: 23129.44 | G12: =F12/SUM($F$2:$F$59) | H12: 26 | I12: =F12/H12 | J12: 53
A13: Hastane (Kurumsal) | B13: Lead Toplama (Form) | C13: Lead - Estetik/Plastik/Saç | D13: Doruk Hastaneleri | E13: CBO / Saç Ekimi - lead / soğuk | F13: 21956.72 | G13: =F13/SUM($F$2:$F$59) | H13: 26 | I13: =F13/H13 | J13: 35
... A59: Doktor Sayfaları | B59: Instagram Öne Çıkarma | C59: Öne Çıkarma - Doktor | D59: Op.Dr. Abdullah ERTAŞ | E59: Instagram gönderisi: 🦴 Omurga Kırıklarında Asıl... | F59: 336.23 | G59: =F59/SUM($F$2:$F$59) | H59: 1 | I59: =F59/H59 | J59: 81
E60: TOPLAM | F60: =SUM(F2:F59) | G60: =SUM(G2:G59)

Sheet 4. 60 Bin TL Dağıtımı
B2: GÜNLÜK 60.000 TL SENARYOSU — Aynı Oranlarda Dağıtım
B3: Geçmiş 30 günlük harcama oranları korunarak, günlük bütçe aşağıdaki "Günlük Bütçe" hücresine göre dağıtılır.
B5: Günlük Bütçe (TL) → | C5: 60000 | D5: ← değiştirin, tüm tablo güncellenir
B6: Aylık Gün Sayısı → | C6: 30
B8: A) ANA KATEGORİYE GÖRE (Hastane / Marka / Doktor)
B9: Kategori | C9: Geçmiş Pay % | D9: Günlük Tutar (TL) | E9: Aylık Tutar (TL)
B10: Hastane (Kurumsal) | C10: =(SUMIFS('Ham Veri (Kategorili)'!$G$2:$G$763,'Ham Veri (Kategorili)'!$D$2:$D$763,"Hastane (Kurumsal)")/SUM('Ham Veri (Kategorili)'!$G$2:$G$763)) | D10: =(SUMIFS('Ham Veri (Kategorili)'!$G$2:$G$763,'Ham Veri (Kategorili)'!$D$2:$D$763,"Hastane (Kurumsal)")/SUM('Ham Veri (Kategorili)'!$G$2:$G$763))*$C$5 | E10: =D10*$C$6
B11: Estetik Marka | C11: =(SUMIFS('Ham Veri (Kategorili)'!$G$2:$G$763,'Ham Veri (Kategorili)'!$D$2:$D$763,"Estetik Marka")/SUM('Ham Veri (Kategorili)'!$G$2:$G$763)) | D11: =(SUMIFS('Ham Veri (Kategorili)'!$G$2:$G$763,'Ham Veri (Kategorili)'!$D$2:$D$763,"Estetik Marka")/SUM('Ham Veri (Kategorili)'!$G$2:$G$763))*$C$5 | E11: =D11*$C$6
B12: Doktor Sayfaları | C12: =(SUMIFS('Ham Veri (Kategorili)'!$G$2:$G$763,'Ham Veri (Kategorili)'!$D$2:$D$763,"Doktor Sayfaları")/SUM('Ham Veri (Kategorili)'!$G$2:$G$763)) | D12: =(SUMIFS('Ham Veri (Kategorili)'!$G$2:$G$763,'Ham Veri (Kategorili)'!$D$2:$D$763,"Doktor Sayfaları")/SUM('Ham Veri (Kategorili)'!$G$2:$G$763))*$C$5 | E12: =D12*$C$6
B13: TOPLAM | C13: =SUM(C10:C12) | D13: =SUM(D10:D12) | E13: =SUM(E10:E12)
B15: B) KAMPANYA AMACINA GÖRE (Lead / Öne Çıkarma / Bilinirlik)
B16: Kategori | C16: Geçmiş Pay % | D16: Günlük Tutar (TL) | E16: Aylık Tutar (TL)
B17: Lead Toplama (Form) | C17: =(SUMIFS('Ham Veri (Kategorili)'!$G$2:$G$763,'Ham Veri (Kategorili)'!$E$2:$E$763,"Lead Toplama (Form)")/SUM('Ham Veri (Kategorili)'!$G$2:$G$763)) | D17: =(SUMIFS('Ham Veri (Kategorili)'!$G$2:$G$763,'Ham Veri (Kategorili)'!$E$2:$E$763,"Lead Toplama (Form)")/SUM('Ham Veri (Kategorili)'!$G$2:$G$763))*$C$5 | E17: =D17*$C$6
B18: Instagram Öne Çıkarma | C18: =(SUMIFS('Ham Veri (Kategorili)'!$G$2:$G$763,'Ham Veri (Kategorili)'!$E$2:$E$763,"Instagram Öne Çıkarma")/SUM('Ham Veri (Kategorili)'!$G$2:$G$763)) | D18: =(SUMIFS('Ham Veri (Kategorili)'!$G$2:$G$763,'Ham Veri (Kategorili)'!$E$2:$E$763,"Instagram Öne Çıkarma")/SUM('Ham Veri (Kategorili)'!$G$2:$G$763))*$C$5 | E18: =D18*$C$6
B19: Marka Bilinirliği (Erişim) | C19: =(SUMIFS('Ham Veri (Kategorili)'!$G$2:$G$763,'Ham Veri (Kategorili)'!$E$2:$E$763,"Marka Bilinirliği (Erişim)")/SUM('Ham Veri (Kategorili)'!$G$2:$G$763)) | D19: =(SUMIFS('Ham Veri (Kategorili)'!$G$2:$G$763,'Ham Veri (Kategorili)'!$E$2:$E$763,"Marka Bilinirliği (Erişim)")/SUM('Ham Veri (Kategorili)'!$G$2:$G$763))*$C$5 | E19: =D19*$C$6
B20: TOPLAM | C20: =SUM(C17:C19) | D20: =SUM(D17:D19) | E20: =SUM(E17:E19)
B22: C) DETAYLI ALT KATEGORİLERE GÖRE (Tam Kırılım)
B23: Kategori | C23: Geçmiş Pay % | D23: Günlük Tutar (TL) | E23: Aylık Tutar (TL)
B24: Lead - Kadın Doğum/Gebe/FTR | C24: =(SUMIFS('Ham Veri (Kategorili)'!$G$2:$G$763,'Ham Veri (Kategorili)'!$F$2:$F$763,"Lead - Kadın Doğum/Gebe/FTR")/SUM('Ham Veri (Kategorili)'!$G$2:$G$763)) | D24: =(SUMIFS('Ham Veri (Kategorili)'!$G$2:$G$763,'Ham Veri (Kategorili)'!$F$2:$F$763,"Lead - Kadın Doğum/Gebe/FTR")/SUM('Ham Veri (Kategorili)'!$G$2:$G$763))*$C$5 | E24: =D24*$C$6
B25: Lead - Estetik/Plastik/Saç | C25: =(SUMIFS('Ham Veri (Kategorili)'!$G$2:$G$763,'Ham Veri (Kategorili)'!$F$2:$F$763,"Lead - Estetik/Plastik/Saç")/SUM('Ham Veri (Kategorili)'!$G$2:$G$763)) | D25: =(SUMIFS('Ham Veri (Kategorili)'!$G$2:$G$763,'Ham Veri (Kategorili)'!$F$2:$F$763,"Lead - Estetik/Plastik/Saç")/SUM('Ham Veri (Kategorili)'!$G$2:$G$763))*$C$5 | E25: =D25*$C$6
B26: Lead - Check-up/Tarama | C26: =(SUMIFS('Ham Veri (Kategorili)'!$G$2:$G$763,'Ham Veri (Kategorili)'!$F$2:$F$763,"Lead - Check-up/Tarama")/SUM('Ham Veri (Kategorili)'!$G$2:$G$763)) | D26: =(SUMIFS('Ham Veri (Kategorili)'!$G$2:$G$763,'Ham Veri (Kategorili)'!$F$2:$F$763,"Lead - Check-up/Tarama")/SUM('Ham Veri (Kategorili)'!$G$2:$G$763))*$C$5 | E26: =D26*$C$6
B27: Lead - İK/İş Başvurusu | C27: =(SUMIFS('Ham Veri (Kategorili)'!$G$2:$G$763,'Ham Veri (Kategorili)'!$F$2:$F$763,"Lead - İK/İş Başvurusu")/SUM('Ham Veri (Kategorili)'!$G$2:$G$763)) | D27: =(SUMIFS('Ham Veri (Kategorili)'!$G$2:$G$763,'Ham Veri (Kategorili)'!$F$2:$F$763,"Lead - İK/İş Başvurusu")/SUM('Ham Veri (Kategorili)'!$G$2:$G$763))*$C$5 | E27: =D27*$C$6
B28: Öne Çıkarma - Doruk Hastaneleri | C28: =(SUMIFS('Ham Veri (Kategorili)'!$G$2:$G$763,'Ham Veri (Kategorili)'!$F$2:$F$763,"Öne Çıkarma - Doruk Hastaneleri")/SUM('Ham Veri (Kategorili)'!$G$2:$G$763)) | D28: =(SUMIFS('Ham Veri (Kategorili)'!$G$2:$G$763,'Ham Veri (Kategorili)'!$F$2:$F$763,"Öne Çıkarma - Doruk Hastaneleri")/SUM('Ham Veri (Kategorili)'!$G$2:$G$763))*$C$5 | E28: =D28*$C$6
B29: Öne Çıkarma - Doktor | C29: =(SUMIFS('Ham Veri (Kategorili)'!$G$2:$G$763,'Ham Veri (Kategorili)'!$F$2:$F$763,"Öne Çıkarma - Doktor")/SUM('Ham Veri (Kategorili)'!$G$2:$G$763)) | D29: =(SUMIFS('Ham Veri (Kategorili)'!$G$2:$G$763,'Ham Veri (Kategorili)'!$F$2:$F$763,"Öne Çıkarma - Doktor")/SUM('Ham Veri (Kategorili)'!$G$2:$G$763))*$C$5 | E29: =D29*$C$6
B30: Öne Çıkarma - Doruk Estetik | C30: =(SUMIFS('Ham Veri (Kategorili)'!$G$2:$G$763,'Ham Veri (Kategorili)'!$F$2:$F$763,"Öne Çıkarma - Doruk Estetik")/SUM('Ham Veri (Kategorili)'!$G$2:$G$763)) | D30: =(SUMIFS('Ham Veri (Kategorili)'!$G$2:$G$763,'Ham Veri (Kategorili)'!$F$2:$F$763,"Öne Çıkarma - Doruk Estetik")/SUM('Ham Veri (Kategorili)'!$G$2:$G$763))*$C$5 | E30: =D30*$C$6
B31: Bilinirlik - Doktor Tanıtım | C31: =(SUMIFS('Ham Veri (Kategorili)'!$G$2:$G$763,'Ham Veri (Kategorili)'!$F$2:$F$763,"Bilinirlik - Doktor Tanıtım")/SUM('Ham Veri (Kategorili)'!$G$2:$G$763)) | D31: =(SUMIFS('Ham Veri (Kategorili)'!$G$2:$G$763,'Ham Veri (Kategorili)'!$F$2:$F$763,"Bilinirlik - Doktor Tanıtım")/SUM('Ham Veri (Kategorili)'!$G$2:$G$763))*$C$5 | E31: =D31*$C$6
B32: Bilinirlik - Kurumsal (ÖSS-TSS) | C32: =(SUMIFS('Ham Veri (Kategorili)'!$G$2:$G$763,'Ham Veri (Kategorili)'!$F$2:$F$763,"Bilinirlik - Kurumsal (ÖSS-TSS)")/SUM('Ham Veri (Kategorili)'!$G$2:$G$763)) | D32: =(SUMIFS('Ham Veri (Kategorili)'!$G$2:$G$763,'Ham Veri (Kategorili)'!$F$2:$F$763,"Bilinirlik - Kurumsal (ÖSS-TSS)")/SUM('Ham Veri (Kategorili)'!$G$2:$G$763))*$C$5 | E32: =D32*$C$6
B33: Bilinirlik - Gebe/Doğum | C33: =(SUMIFS('Ham Veri (Kategorili)'!$G$2:$G$763,'Ham Veri (Kategorili)'!$F$2:$F$763,"Bilinirlik - Gebe/Doğum")/SUM('Ham Veri (Kategorili)'!$G$2:$G$763)) | D33: =(SUMIFS('Ham Veri (Kategorili)'!$G$2:$G$763,'Ham Veri (Kategorili)'!$F$2:$F$763,"Bilinirlik - Gebe/Doğum")/SUM('Ham Veri (Kategorili)'!$G$2:$G$763))*$C$5 | E33: =D33*$C$6
B34: TOPLAM | C34: =SUM(C24:C33) | D34: =SUM(D24:D33) | E34: =SUM(E24:E33)
B36: Not: Yüzdeler 23 Haz–22 Tem 2026 gerçekleşen harcamalardan otomatik hesaplanır. Sarı hücreleri değiştirerek farklı bütçe/gün senaryoları görebilirsiniz.

Sheet 5. Sayfa x Amaç Matrisi
B2: SAYFA KATEGORİSİ × KAMPANYA AMACI MATRİSİ
B3: Her sayfa kategorisinin altında amaçlar; tutar + oran + günlük 60.000 TL karşılığı. (Genel% = toplam içindeki pay, Sayfa-İçi% = o sayfanın kendi içindeki pay)
B5: Günlük Bütçe (TL) → | D5: 60000
B7: Sayfa Kategorisi | C7: Amaç | D7: Harcama 30g (TL) | E7: Genel % | F7: Sayfa-İçi % | G7: Günlük (60K) | H7: Aylık (60K)
B8: Hastane (Kurumsal) | C8: Lead Toplama (Form) | D8: =SUMIFS('Ham Veri (Kategorili)'!$G$2:$G$763,'Ham Veri (Kategorili)'!$D$2:$D$763,"Hastane (Kurumsal)",'Ham Veri (Kategorili)'!$E$2:$E$763,"Lead Toplama (Form)") | E8: =SUMIFS('Ham Veri (Kategorili)'!$G$2:$G$763,'Ham Veri (Kategorili)'!$D$2:$D$763,"Hastane (Kurumsal)",'Ham Veri (Kategorili)'!$E$2:$E$763,"Lead Toplama (Form)")/SUM('Ham Veri (Kategorili)'!$G$2:$G$763) | F8: =SUMIFS('Ham Veri (Kategorili)'!$G$2:$G$763,'Ham Veri (Kategorili)'!$D$2:$D$763,"Hastane (Kurumsal)",'Ham Veri (Kategorili)'!$E$2:$E$763,"Lead Toplama (Form)")/SUMIFS('Ham Veri (Kategorili)'!$G$2:$G$763,'Ham Veri (Kategorili)'!$D$2:$D$763,"Hastane (Kurumsal)") | G8: =(SUMIFS('Ham Veri (Kategorili)'!$G$2:$G$763,'Ham Veri (Kategorili)'!$D$2:$D$763,"Hastane (Kurumsal)",'Ham Veri (Kategorili)'!$E$2:$E$763,"Lead Toplama (Form)")/SUM('Ham Veri (Kategorili)'!$G$2:$G$763))*$D$5 | H8: =G8*30
C9: Instagram Öne Çıkarma | D9: =SUMIFS('Ham Veri (Kategorili)'!$G$2:$G$763,'Ham Veri (Kategorili)'!$D$2:$D$763,"Hastane (Kurumsal)",'Ham Veri (Kategorili)'!$E$2:$E$763,"Instagram Öne Çıkarma") | E9: =SUMIFS('Ham Veri (Kategorili)'!$G$2:$G$763,'Ham Veri (Kategorili)'!$D$2:$D$763,"Hastane (Kurumsal)",'Ham Veri (Kategorili)'!$E$2:$E$763,"Instagram Öne Çıkarma")/SUM('Ham Veri (Kategorili)'!$G$2:$G$763) | F9: =SUMIFS('Ham Veri (Kategorili)'!$G$2:$G$763,'Ham Veri (Kategorili)'!$D$2:$D$763,"Hastane (Kurumsal)",'Ham Veri (Kategorili)'!$E$2:$E$763,"Instagram Öne Çıkarma")/SUMIFS('Ham Veri (Kategorili)'!$G$2:$G$763,'Ham Veri (Kategorili)'!$D$2:$D$763,"Hastane (Kurumsal)") | G9: =(SUMIFS('Ham Veri (Kategorili)'!$G$2:$G$763,'Ham Veri (Kategorili)'!$D$2:$D$763,"Hastane (Kurumsal)",'Ham Veri (Kategorili)'!$E$2:$E$763,"Instagram Öne Çıkarma")/SUM('Ham Veri (Kategorili)'!$G$2:$G$763))*$D$5 | H9: =G9*30
C10: Marka Bilinirliği (Erişim) | D10: =SUMIFS('Ham Veri (Kategorili)'!$G$2:$G$763,'Ham Veri (Kategorili)'!$D$2:$D$763,"Hastane (Kurumsal)",'Ham Veri (Kategorili)'!$E$2:$E$763,"Marka Bilinirliği (Erişim)") | E10: =SUMIFS('Ham Veri (Kategorili)'!$G$2:$G$763,'Ham Veri (Kategorili)'!$D$2:$D$763,"Hastane (Kurumsal)",'Ham Veri (Kategorili)'!$E$2:$E$763,"Marka Bilinirliği (Erişim)")/SUM('Ham Veri (Kategorili)'!$G$2:$G$763) | F10: =SUMIFS('Ham Veri (Kategorili)'!$G$2:$G$763,'Ham Veri (Kategorili)'!$D$2:$D$763,"Hastane (Kurumsal)",'Ham Veri (Kategorili)'!$E$2:$E$763,"Marka Bilinirliği (Erişim)")/SUMIFS('Ham Veri (Kategorili)'!$G$2:$G$763,'Ham Veri (Kategorili)'!$D$2:$D$763,"Hastane (Kurumsal)") | G10: =(SUMIFS('Ham Veri (Kategorili)'!$G$2:$G$763,'Ham Veri (Kategorili)'!$D$2:$D$763,"Hastane (Kurumsal)",'Ham Veri (Kategorili)'!$E$2:$E$763,"Marka Bilinirliği (Erişim)")/SUM('Ham Veri (Kategorili)'!$G$2:$G$763))*$D$5 | H10: =G10*30
C11: — ALT TOPLAM | D11: =SUM(D8:D10) | E11: =SUM(E8:E10) | F11: =SUM(F8:F10) | G11: =SUM(G8:G10) | H11: =SUM(H8:H10)
B12: Estetik Marka | C12: Lead Toplama (Form) | D12: =SUMIFS('Ham Veri (Kategorili)'!$G$2:$G$763,'Ham Veri (Kategorili)'!$D$2:$D$763,"Estetik Marka",'Ham Veri (Kategorili)'!$E$2:$E$763,"Lead Toplama (Form)") | E12: =SUMIFS('Ham Veri (Kategorili)'!$G$2:$G$763,'Ham Veri (Kategorili)'!$D$2:$D$763,"Estetik Marka",'Ham Veri (Kategorili)'!$E$2:$E$763,"Lead Toplama (Form)")/SUM('Ham Veri (Kategorili)'!$G$2:$G$763) | F12: =SUMIFS('Ham Veri (Kategorili)'!$G$2:$G$763,'Ham Veri (Kategorili)'!$D$2:$D$763,"Estetik Marka",'Ham Veri (Kategorili)'!$E$2:$E$763,"Lead Toplama (Form)")/SUMIFS('Ham Veri (Kategorili)'!$G$2:$G$763,'Ham Veri (Kategorili)'!$D$2:$D$763,"Estetik Marka") | G12: =(SUMIFS('Ham Veri (Kategorili)'!$G$2:$G$763,'Ham Veri (Kategorili)'!$D$2:$D$763,"Estetik Marka",'Ham Veri (Kategorili)'!$E$2:$E$763,"Lead Toplama (Form)")/SUM('Ham Veri (Kategorili)'!$G$2:$G$763))*$D$5 | H12: =G12*30
C13: Instagram Öne Çıkarma | D13: =SUMIFS('Ham Veri (Kategorili)'!$G$2:$G$763,'Ham Veri (Kategorili)'!$D$2:$D$763,"Estetik Marka",'Ham Veri (Kategorili)'!$E$2:$E$763,"Instagram Öne Çıkarma") | E13: =SUMIFS('Ham Veri (Kategorili)'!$G$2:$G$763,'Ham Veri (Kategorili)'!$D$2:$D$763,"Estetik Marka",'Ham Veri (Kategorili)'!$E$2:$E$763,"Instagram Öne Çıkarma")/SUM('Ham Veri (Kategorili)'!$G$2:$G$763) | F13: =SUMIFS('Ham Veri (Kategorili)'!$G$2:$G$763,'Ham Veri (Kategorili)'!$D$2:$D$763,"Estetik Marka",'Ham Veri (Kategorili)'!$E$2:$E$763,"Instagram Öne Çıkarma")/SUMIFS('Ham Veri (Kategorili)'!$G$2:$G$763,'Ham Veri (Kategorili)'!$D$2:$D$763,"Estetik Marka") | G13: =(SUMIFS('Ham Veri (Kategorili)'!$G$2:$G$763,'Ham Veri (Kategorili)'!$D$2:$D$763,"Estetik Marka",'Ham Veri (Kategorili)'!$E$2:$E$763,"Instagram Öne Çıkarma")/SUM('Ham Veri (Kategorili)'!$G$2:$G$763))*$D$5 | H13: =G13*30
C14: — ALT TOPLAM | D14: =SUM(D12:D13) | E14: =SUM(E12:E13) | F14: =SUM(F12:F13) | G14: =SUM(G12:G13) | H14: =SUM(H12:H13)
B15: Doktor Sayfaları | C15: Instagram Öne Çıkarma | D15: =SUMIFS('Ham Veri (Kategorili)'!$G$2:$G$763,'Ham Veri (Kategorili)'!$D$2:$D$763,"Doktor Sayfaları",'Ham Veri (Kategorili)'!$E$2:$E$763,"Instagram Öne Çıkarma") | E15: =SUMIFS('Ham Veri (Kategorili)'!$G$2:$G$763,'Ham Veri (Kategorili)'!$D$2:$D$763,"Doktor Sayfaları",'Ham Veri (Kategorili)'!$E$2:$E$763,"Instagram Öne Çıkarma")/SUM('Ham Veri (Kategorili)'!$G$2:$G$763) | F15: =SUMIFS('Ham Veri (Kategorili)'!$G$2:$G$763,'Ham Veri (Kategorili)'!$D$2:$D$763,"Doktor Sayfaları",'Ham Veri (Kategorili)'!$E$2:$E$763,"Instagram Öne Çıkarma")/SUMIFS('Ham Veri (Kategorili)'!$G$2:$G$763,'Ham Veri (Kategorili)'!$D$2:$D$763,"Doktor Sayfaları") | G15: =(SUMIFS('Ham Veri (Kategorili)'!$G$2:$G$763,'Ham Veri (Kategorili)'!$D$2:$D$763,"Doktor Sayfaları",'Ham Veri (Kategorili)'!$E$2:$E$763,"Instagram Öne Çıkarma")/SUM('Ham Veri (Kategorili)'!$G$2:$G$763))*$D$5 | H15: =G15*30
C16: — ALT TOPLAM | D16: =SUM(D15:D15) | E16: =SUM(E15:E15) | F16: =SUM(F15:F15) | G16: =SUM(G15:G15) | H16: =SUM(H15:H15)
B17: GENEL TOPLAM | D17: =SUM('Ham Veri (Kategorili)'!$G$2:$G$763) | E17: =SUM('Ham Veri (Kategorili)'!$G$2:$G$763)/SUM('Ham Veri (Kategorili)'!$G$2:$G$763) | G17: =$D$5 | H17: =$D$5*30

Sheet 6. Doktor Artış Senaryoları
B2: GÜNLÜK 60.000 TL — DOKTOR ARTIŞ SENARYOLARI
B3: Baz 60.000 TL dağılımı aynı oranlarda korunur; ek bütçe YALNIZCA doktor sayfalarına, üstüne eklenir. Diğer kalemler sabit kalır.
B5: Baz Günlük Bütçe (TL) → | C5: 60000
B6: Senaryo 2 — Doktora Ek (TL) → | C6: 10000
B7: Senaryo 3 — Doktora Ek (TL) → | C7: 20000
B9: GÜNLÜK DAĞILIM (TL/gün)
B10: Sayfa Kategorisi | C10: Senaryo 1 (Baz 60K) | D10: Senaryo 2 (+10K Doktor) | E10: Senaryo 3 (+20K Doktor)
B11: Hastane (Kurumsal) | C11: =(SUMIFS('Ham Veri (Kategorili)'!$G$2:$G$763,'Ham Veri (Kategorili)'!$D$2:$D$763,"Hastane (Kurumsal)")/SUM('Ham Veri (Kategorili)'!$G$2:$G$763))*$C$5 | D11: =(SUMIFS('Ham Veri (Kategorili)'!$G$2:$G$763,'Ham Veri (Kategorili)'!$D$2:$D$763,"Hastane (Kurumsal)")/SUM('Ham Veri (Kategorili)'!$G$2:$G$763))*$C$5 | E11: =(SUMIFS('Ham Veri (Kategorili)'!$G$2:$G$763,'Ham Veri (Kategorili)'!$D$2:$D$763,"Hastane (Kurumsal)")/SUM('Ham Veri (Kategorili)'!$G$2:$G$763))*$C$5
B12: Estetik Marka | C12: =(SUMIFS('Ham Veri (Kategorili)'!$G$2:$G$763,'Ham Veri (Kategorili)'!$D$2:$D$763,"Estetik Marka")/SUM('Ham Veri (Kategorili)'!$G$2:$G$763))*$C$5 | D12: =(SUMIFS('Ham Veri (Kategorili)'!$G$2:$G$763,'Ham Veri (Kategorili)'!$D$2:$D$763,"Estetik Marka")/SUM('Ham Veri (Kategorili)'!$G$2:$G$763))*$C$5 | E12: =(SUMIFS('Ham Veri (Kategorili)'!$G$2:$G$763,'Ham Veri (Kategorili)'!$D$2:$D$763,"Estetik Marka")/SUM('Ham Veri (Kategorili)'!$G$2:$G$763))*$C$5
B13: Doktor Sayfaları | C13: =(SUMIFS('Ham Veri (Kategorili)'!$G$2:$G$763,'Ham Veri (Kategorili)'!$D$2:$D$763,"Doktor Sayfaları")/SUM('Ham Veri (Kategorili)'!$G$2:$G$763))*$C$5 | D13: =(SUMIFS('Ham Veri (Kategorili)'!$G$2:$G$763,'Ham Veri (Kategorili)'!$D$2:$D$763,"Doktor Sayfaları")/SUM('Ham Veri (Kategorili)'!$G$2:$G$763))*$C$5+$C$6 | E13: =(SUMIFS('Ham Veri (Kategorili)'!$G$2:$G$763,'Ham Veri (Kategorili)'!$D$2:$D$763,"Doktor Sayfaları")/SUM('Ham Veri (Kategorili)'!$G$2:$G$763))*$C$5+$C$7
B14: GÜNLÜK TOPLAM | C14: =SUM(C11:C13) | D14: =SUM(D11:D13) | E14: =SUM(E11:E13)
B15: → Doktor payı (% toplam) | C15: =C13/C14 | D15: =D13/D14 | E15: =E13/E14
B17: AYLIK DAĞILIM (TL/ay = günlük × 30)
B18: Sayfa Kategorisi | C18: Senaryo 1 (Baz 60K) | D18: Senaryo 2 (+10K Doktor) | E18: Senaryo 3 (+20K Doktor)
B19: Hastane (Kurumsal) | C19: =C11*30 | D19: =D11*30 | E19: =E11*30
B20: Estetik Marka | C20: =C12*30 | D20: =D12*30 | E20: =E12*30
B21: Doktor Sayfaları | C21: =C13*30 | D21: =D13*30 | E21: =E13*30
B22: AYLIK TOPLAM | C22: =SUM(C19:C21) | D22: =SUM(D19:D21) | E22: =SUM(E19:E21)
B24: DOKTOR BAZINDA GÜNLÜK (ek, geçmiş paya göre 4 doktora bölünür)
B25: Doktor | C25: Senaryo 1 (Baz) | D25: Senaryo 2 (+10K) | E25: Senaryo 3 (+20K)
B26: Op.Dr. Abdullah ERTAŞ | C26: =(SUMIFS('Ham Veri (Kategorili)'!$G$2:$G$763,'Ham Veri (Kategorili)'!$A$2:$A$763,"Op.Dr. Abdullah ERTAŞ")/SUMIFS('Ham Veri (Kategorili)'!$G$2:$G$763,'Ham Veri (Kategorili)'!$D$2:$D$763,"Doktor Sayfaları"))*((SUMIFS('Ham Veri (Kategorili)'!$G$2:$G$763,'Ham Veri (Kategorili)'!$D$2:$D$763,"Doktor Sayfaları")/SUM('Ham Veri (Kategorili)'!$G$2:$G$763))*$C$5) | D26: =(SUMIFS('Ham Veri (Kategorili)'!$G$2:$G$763,'Ham Veri (Kategorili)'!$A$2:$A$763,"Op.Dr. Abdullah ERTAŞ")/SUMIFS('Ham Veri (Kategorili)'!$G$2:$G$763,'Ham Veri (Kategorili)'!$D$2:$D$763,"Doktor Sayfaları"))*((SUMIFS('Ham Veri (Kategorili)'!$G$2:$G$763,'Ham Veri (Kategorili)'!$D$2:$D$763,"Doktor Sayfaları")/SUM('Ham Veri (Kategorili)'!$G$2:$G$763))*$C$5+$C$6) | E26: =(SUMIFS('Ham Veri (Kategorili)'!$G$2:$G$763,'Ham Veri (Kategorili)'!$A$2:$A$763,"Op.Dr. Abdullah ERTAŞ")/SUMIFS('Ham Veri (Kategorili)'!$G$2:$G$763,'Ham Veri (Kategorili)'!$D$2:$D$763,"Doktor Sayfaları"))*((SUMIFS('Ham Veri (Kategorili)'!$G$2:$G$763,'Ham Veri (Kategorili)'!$D$2:$D$763,"Doktor Sayfaları")/SUM('Ham Veri (Kategorili)'!$G$2:$G$763))*$C$5+$C$7)
B27: Op. Dr. Emre Çaycı | C27: =(SUMIFS('Ham Veri (Kategorili)'!$G$2:$G$763,'Ham Veri (Kategorili)'!$A$2:$A$763,"Op. Dr. Emre Çaycı")/SUMIFS('Ham Veri (Kategorili)'!$G$2:$G$763,'Ham Veri (Kategorili)'!$D$2:$D$763,"Doktor Sayfaları"))*((SUMIFS('Ham Veri (Kategorili)'!$G$2:$G$763,'Ham Veri (Kategorili)'!$D$2:$D$763,"Doktor Sayfaları")/SUM('Ham Veri (Kategorili)'!$G$2:$G$763))*$C$5) | D27: =(SUMIFS('Ham Veri (Kategorili)'!$G$2:$G$763,'Ham Veri (Kategorili)'!$A$2:$A$763,"Op. Dr. Emre Çaycı")/SUMIFS('Ham Veri (Kategorili)'!$G$2:$G$763,'Ham Veri (Kategorili)'!$D$2:$D$763,"Doktor Sayfaları"))*((SUMIFS('Ham Veri (Kategorili)'!$G$2:$G$763,'Ham Veri (Kategorili)'!$D$2:$D$763,"Doktor Sayfaları")/SUM('Ham Veri (Kategorili)'!$G$2:$G$763))*$C$5+$C$6) | E27: =(SUMIFS('Ham Veri (Kategorili)'!$G$2:$G$763,'Ham Veri (Kategorili)'!$A$2:$A$763,"Op. Dr. Emre Çaycı")/SUMIFS('Ham Veri (Kategorili)'!$G$2:$G$763,'Ham Veri (Kategorili)'!$D$2:$D$763,"Doktor Sayfaları"))*((SUMIFS('Ham Veri (Kategorili)'!$G$2:$G$763,'Ham Veri (Kategorili)'!$D$2:$D$763,"Doktor Sayfaları")/SUM('Ham Veri (Kategorili)'!$G$2:$G$763))*$C$5+$C$7)
B28: Op.Dr. Eren Kaya | C28: =(SUMIFS('Ham Veri (Kategorili)'!$G$2:$G$763,'Ham Veri (Kategorili)'!$A$2:$A$763,"Op.Dr. Eren Kaya")/SUMIFS('Ham Veri (Kategorili)'!$G$2:$G$763,'Ham Veri (Kategorili)'!$D$2:$D$763,"Doktor Sayfaları"))*((SUMIFS('Ham Veri (Kategorili)'!$G$2:$G$763,'Ham Veri (Kategorili)'!$D$2:$D$763,"Doktor Sayfaları")/SUM('Ham Veri (Kategorili)'!$G$2:$G$763))*$C$5) | D28: =(SUMIFS('Ham Veri (Kategorili)'!$G$2:$G$763,'Ham Veri (Kategorili)'!$A$2:$A$763,"Op.Dr. Eren Kaya")/SUMIFS('Ham Veri (Kategorili)'!$G$2:$G$763,'Ham Veri (Kategorili)'!$D$2:$D$763,"Doktor Sayfaları"))*((SUMIFS('Ham Veri (Kategorili)'!$G$2:$G$763,'Ham Veri (Kategorili)'!$D$2:$D$763,"Doktor Sayfaları")/SUM('Ham Veri (Kategorili)'!$G$2:$G$763))*$C$5+$C$6) | E28: =(SUMIFS('Ham Veri (Kategorili)'!$G$2:$G$763,'Ham Veri (Kategorili)'!$A$2:$A$763,"Op.Dr. Eren Kaya")/SUMIFS('Ham Veri (Kategorili)'!$G$2:$G$763,'Ham Veri (Kategorili)'!$D$2:$D$763,"Doktor Sayfaları"))*((SUMIFS('Ham Veri (Kategorili)'!$G$2:$G$763,'Ham Veri (Kategorili)'!$D$2:$D$763,"Doktor Sayfaları")/SUM('Ham Veri (Kategorili)'!$G$2:$G$763))*$C$5+$C$7)
B29: Doç.Dr. Selin Aktürk Esen | C29: =(SUMIFS('Ham Veri (Kategorili)'!$G$2:$G$763,'Ham Veri (Kategorili)'!$A$2:$A$763,"Doç.Dr. Selin Aktürk Esen")/SUMIFS('Ham Veri (Kategorili)'!$G$2:$G$763,'Ham Veri (Kategorili)'!$D$2:$D$763,"Doktor Sayfaları"))*((SUMIFS('Ham Veri (Kategorili)'!$G$2:$G$763,'Ham Veri (Kategorili)'!$D$2:$D$763,"Doktor Sayfaları")/SUM('Ham Veri (Kategorili)'!$G$2:$G$763))*$C$5) | D29: =(SUMIFS('Ham Veri (Kategorili)'!$G$2:$G$763,'Ham Veri (Kategorili)'!$A$2:$A$763,"Doç.Dr. Selin Aktürk Esen")/SUMIFS('Ham Veri (Kategorili)'!$G$2:$G$763,'Ham Veri (Kategorili)'!$D$2:$D$763,"Doktor Sayfaları"))*((SUMIFS('Ham Veri (Kategorili)'!$G$2:$G$763,'Ham Veri (Kategorili)'!$D$2:$D$763,"Doktor Sayfaları")/SUM('Ham Veri (Kategorili)'!$G$2:$G$763))*$C$5+$C$6) | E29: =(SUMIFS('Ham Veri (Kategorili)'!$G$2:$G$763,'Ham Veri (Kategorili)'!$A$2:$A$763,"Doç.Dr. Selin Aktürk Esen")/SUMIFS('Ham Veri (Kategorili)'!$G$2:$G$763,'Ham Veri (Kategorili)'!$D$2:$D$763,"Doktor Sayfaları"))*((SUMIFS('Ham Veri (Kategorili)'!$G$2:$G$763,'Ham Veri (Kategorili)'!$D$2:$D$763,"Doktor Sayfaları")/SUM('Ham Veri (Kategorili)'!$G$2:$G$763))*$C$5+$C$7)
B30: DOKTOR TOPLAM | C30: =SUM(C26:C29) | D30: =SUM(D26:D29) | E30: =SUM(E26:E29)
B32: Not: Senaryo 1 = 60.000 TL'nin geçmiş oranlarla dağılımı (doktor payı ≈ %6,2).
B33: Senaryo 2 = Senaryo 1 + doktora ek 10.000 TL → günlük toplam 70.000 TL.
B34: Senaryo 3 = Senaryo 1 + doktora ek 20.000 TL → günlük toplam 80.000 TL.
B35: Hastane ve Estetik kalemleri üç senaryoda da sabittir; yalnızca doktor bütçesi artar.
B36: Sarı hücreleri (baz bütçe / ek tutarlar) değiştirerek kendi senaryolarınızı üretebilirsiniz.

Sheet Ham Veri (Kategorili)
A1: Sayfa Adı | B1: Kampanya Adı | C1: Gün | D1: Ana Kategori | E1: Kampanya Amacı | F1: Alt Kategori | G1: Harcama (TL) | H1: Sonuç Türü | I1: Sonuç | J1: Erişim | K1: Gösterim
A2: Op. Dr. Emre Çaycı | B2: Instagram gönderisi: 👨‍⚕️ Jinekomasti Ameliyatı... | C2: 2026-07-13 | D2: Doktor Sayfaları | E2: Instagram Öne Çıkarma | F2: Öne Çıkarma - Doktor | G2: 1542.27 | H2: Instagram profili ziyaretleri | I2: 1438 | J2: 42542 | K2: 46881
A3: Op. Dr. Emre Çaycı | B3: Instagram gönderisi: 👨‍⚕️ Jinekomasti Ameliyatı... | C3: 2026-07-08 | D3: Doktor Sayfaları | E3: Instagram Öne Çıkarma | F3: Öne Çıkarma - Doktor | G3: 1281.84 | H3: Instagram profili ziyaretleri | I3: 1138 | J3: 29182 | K3: 31027
A4: Op. Dr. Emre Çaycı | B4: Instagram gönderisi: 👨‍⚕️ Jinekomasti Ameliyatı... | C4: 2026-07-10 | D4: Doktor Sayfaları | E4: Instagram Öne Çıkarma | F4: Öne Çıkarma - Doktor | G4: 1281.69 | H4: Instagram profili ziyaretleri | I4: 1232 | J4: 37113 | K4: 38662
A5: Op. Dr. Emre Çaycı | B5: Instagram gönderisi: 💪 Jinekomastide Spor Yeterli... | C5: 2026-06-26 | D5: Doktor Sayfaları | E5: Instagram Öne Çıkarma | F5: Öne Çıkarma - Doktor | G5: 1265.61 | H5: Instagram profili ziyaretleri | I5: 188 | J5: 9385 | K5: 9903
A6: Op. Dr. Emre Çaycı | B6: Instagram gönderisi: 💪 Yağlanma mı, Jinekomasti... | C6: 2026-06-26 | D6: Doktor Sayfaları | E6: Instagram Öne Çıkarma | F6: Öne Çıkarma - Doktor | G6: 1258.54 | H6: Instagram profili ziyaretleri | I6: 245 | J6: 14364 | K6: 15303
A7: Op.Dr. Eren Kaya | B7: Instagram gönderisi: “Erken gebelikte kanama... | C7: 2026-06-26 | D7: Doktor Sayfaları | E7: Instagram Öne Çıkarma | F7: Öne Çıkarma - Doktor | G7: 1258.31 | H7: Instagram profili ziyaretleri | I7: 318 | J7: 15657 | K7: 18009
A8: Op.Dr. Abdullah ERTAŞ | B8: Instagram gönderisi: 🦴 Omurga Kanal Darlığı... | C8: 2026-06-26 | D8: Doktor Sayfaları | E8: Instagram Öne Çıkarma | F8: Öne Çıkarma - Doktor | G8: 1253.68 | H8: Instagram profili ziyaretleri | I8: 269 | J8: 12192 | K8: 12862
A9: Op.Dr. Eren Kaya | B9: Instagram gönderisi: “Rahim alınacaksa... | C9: 2026-06-26 | D9: Doktor Sayfaları | E9: Instagram Öne Çıkarma | F9: Öne Çıkarma - Doktor | G9: 1250.66 | H9: Instagram profili ziyaretleri | I9: 331 | J9: 14113 | K9: 15031
A10: Op.Dr. Abdullah ERTAŞ | B10: Instagram gönderisi: 🧠 Baş Ağrısı İlk Belirti... | C10: 2026-06-26 | D10: Doktor Sayfaları | E10: Instagram Öne Çıkarma | F10: Öne Çıkarma - Doktor | G10: 1240.71 | H10: Instagram profili ziyaretleri | I10: 148 | J10: 12412 | K10: 12747
A11: Doç.Dr. Selin Aktürk Esen | B11: Instagram gönderisi: 🌡️ Kemoterapi Alan... | C11: 2026-06-26 | D11: Doktor Sayfaları | E11: Instagram Öne Çıkarma | F11: Öne Çıkarma - Doktor | G11: 1232.5 | H11: Instagram profili ziyaretleri | I11: 216 | J11: 9065 | K11: 9520
A12: Op.Dr. Abdullah ERTAŞ | B12: Instagram gönderisi: 🦴 Kuyruk Sokumu Ağrısı Neden... | C12: 2026-07-01 | D12: Doktor Sayfaları | E12: Instagram Öne Çıkarma | F12: Öne Çıkarma - Doktor | G12: 1098.92 | H12: Instagram profili ziyaretleri | I12: 282 | J12: 14549 | K12: 15929
A13: Op.Dr. Abdullah ERTAŞ | B13: Instagram gönderisi: 🧠 MR Raporunda Her Yazan... | C13: 2026-07-04 | D13: Doktor Sayfaları | E13: Instagram Öne Çıkarma | F13: Öne Çıkarma - Doktor | G13: 1081.29 | H13: Instagram profili ziyaretleri | I13: 304 | J13: 12301 | K13: 13827
... A347: Doruk Hastaneleri | B347: ABO / Meme Estetiği / plastik cerrahi / lead | C347: 2026-07-18 | D347: Hastane (Kurumsal) | E347: Lead Toplama (Form) | F347: Lead - Estetik/Plastik/Saç | G347: 1193.3 | H347: Potansiyel müşteriler (form) | I347: 1 | J347: 7646 | K347: 10573
A348: Doruk Hastaneleri | B348: CBO / Saç Ekimi - lead / soğuk | C348: 2026-07-18 | D348: Hastane (Kurumsal) | E348: Lead Toplama (Form) | F348: Lead - Estetik/Plastik/Saç | G348: 1190.17 | I348: 0 | J348: 4626 | K348: 7701
A349: Doruk Hastaneleri | B349: ABO / Meme Estetiği / plastik cerrahi / lead | C349: 2026-06-26 | D349: Hastane (Kurumsal) | E349: Lead Toplama (Form) | F349: Lead - Estetik/Plastik/Saç | G349: 1181.48 | H349: Potansiyel müşteriler (form) | I349: 2 | J349: 11760 | K349: 13749
A350: Doruk Hastaneleri | B350: CBO / Saç Ekimi - lead / soğuk | C350: 2026-07-01 | D350: Hastane (Kurumsal) | E350: Lead Toplama (Form) | F350: Lead - Estetik/Plastik/Saç | G350: 1173.95 | H350: Potansiyel müşteriler (form) | I350: 2 | J350: 4340 | K350: 6241
A351: Doruk Hastaneleri | B351: CBO / Saç Ekimi - lead / soğuk | C351: 2026-07-13 | D351: Hastane (Kurumsal) | E351: Lead Toplama (Form) | F351: Lead - Estetik/Plastik/Saç | G351: 1153.21 | H351: Potansiyel müşteriler (form) | I351: 1 | J351: 5661 | K351: 8456
A352: Doruk Hastaneleri | B352: Checkup - genel - lead | C352: 2026-06-28 | D352: Hastane (Kurumsal) | E352: Lead Toplama (Form) | F352: Lead - Check-up/Tarama | G352: 1147.83 | I352: 0 | J352: 7553 | K352: 10200
A353: Doruk Hastaneleri | B353: FTR Yatılı - lead | C353: 2026-07-11 | D353: Hastane (Kurumsal) | E353: Lead Toplama (Form) | F353: Lead - Kadın Doğum/Gebe/FTR | G353: 1144.57 | H353: Potansiyel müşteriler (form) | I353: 1 | J353: 14844 | K353: 15706
A354: Doruk Hastaneleri | B354: Checkup - genel - lead | C354: 2026-07-01 | D354: Hastane (Kurumsal) | E354: Lead Toplama (Form) | F354: Lead - Check-up/Tarama | G354: 1126.55 | H354: Potansiyel müşteriler (form) | I354: 4 | J354: 9017 | K354: 11925
A355: Doruk Hastaneleri | B355: Uzman Hekim Başvuru | C355: 2026-07-01 | D355: Hastane (Kurumsal) | E355: Lead Toplama (Form) | F355: Lead - İK/İş Başvurusu | G355: 1124.46 | H355: Potansiyel müşteriler (form) | I355: 13 | J355: 6961 | K355: 9611
A356: Doruk Hastaneleri | B356: Hemşire İş Başvuru - lead | C356: 2026-07-01 | D356: Hastane (Kurumsal) | E356: Lead Toplama (Form) | F356: Lead - İK/İş Başvurusu | G356: 1124.21 | H356: Potansiyel müşteriler (form) | I356: 2 | J356: 9673 | K356: 16831
A357: Doruk Hastaneleri | B357: CBO / Saç Ekimi - lead / soğuk | C357: 2026-07-08 | D357: Hastane (Kurumsal) | E357: Lead Toplama (Form) | F357: Lead - Estetik/Plastik/Saç | G357: 1124.11 | H357: Potansiyel müşteriler (form) | I357: 4 | J357: 3739 | K357: 6303
A358: Doruk Hastaneleri | B358: CBO / Saç Ekimi - lead / soğuk | C358: 2026-06-28 | D358: Hastane (Kurumsal) | E358: Lead Toplama (Form) | F358: Lead - Estetik/Plastik/Saç | G358: 1116.35 | H358: Potansiyel müşteriler (form) | I358: 1 | J358: 4105 | K358: 6141
A359: Doruk Hastaneleri | B359: ABO / Meme Estetiği / plastik cerrahi / lead | C359: 2026-06-28 | D359: Hastane (Kurumsal) | E359: Lead Toplama (Form) | F359: Lead - Estetik/Plastik/Saç | G359: 1092.75 | H359: Potansiyel müşteriler (form) | I359: 2 | J359: 7271 | K359: 9520
A360: Doruk Hastaneleri | B360: Checkup - genel - lead | C360: 2026-07-02 | D360: Hastane (Kurumsal) | E360: Lead Toplama (Form) | F360: Lead - Check-up/Tarama | G360: 1090.83 | H360: Potansiyel müşteriler (form) | I360: 4 | J360: 7798 | K360: 10128
A361: Doruk Hastaneleri | B361: CBO / Saç Ekimi - lead / soğuk | C361: 2026-06-23 | D361: Hastane (Kurumsal) | E361: Lead Toplama (Form) | F361: Lead - Estetik/Plastik/Saç | G361: 1086.93 | H361: Potansiyel müşteriler (form) | I361: 2 | J361: 4417 | K361: 6132
A362: Doruk Hastaneleri | B362: Hemşire İş Başvuru - lead | C362: 2026-06-28 | D362: Hastane (Kurumsal) | E362: Lead Toplama (Form) | F362: Lead - İK/İş Başvurusu | G362: 1085.97 | H362: Potansiyel müşteriler (form) | I362: 3 | J362: 8503 | K362: 14358
A363: Doruk Hastaneleri | B363: ABO / Meme Estetiği / plastik cerrahi / lead | C363: 2026-07-01 | D363: Hastane (Kurumsal) | E363: Lead Toplama (Form) | F363: Lead - Estetik/Plastik/Saç | G363: 1085.06 | H363: Potansiyel müşteriler (form) | I363: 3 | J363: 7362 | K363: 9835
A364: Doruk Hastaneleri | B364: Uzman Hekim Başvuru | C364: 2026-07-15 | D364: Hastane (Kurumsal) | E364: Lead Toplama (Form) | F364: Lead - İK/İş Başvurusu | G364: 1083.71 | H364: Potansiyel müşteriler (form) | I364: 5 | J364: 6905 | K364: 8499
... A367: Doruk Hastaneleri | B367: Uzman Hekim Başvuru | C367: 2026-06-28 | D367: Hastane (Kurumsal) | E367: Lead Toplama (Form) | F367: Lead - İK/İş Başvurusu | G367: 1068.86 | H367: Potansiyel müşteriler (form) | I367: 5 | J367: 5537 | K367: 7131
A368: Doruk Hastaneleri | B368: CBO / Saç Ekimi - lead / soğuk | C368: 2026-07-02 | D368: Hastane (Kurumsal) | E368: Lead Toplama (Form) | F368: Lead - Estetik/Plastik/Saç | G368: 1064.67 | I368: 0 | J368: 3329 | K368: 5358
A369: Doruk Hastaneleri | B369: ABO / Meme Estetiği / plastik cerrahi / lead | C369: 2026-07-08 | D369: Hastane (Kurumsal) | E369: Lead Toplama (Form) | F369: Lead - Estetik/Plastik/Saç | G369: 1064.24 | H369: Potansiyel müşteriler (form) | I369: 6 | J369: 7955 | K369: 10260
A370: Doruk Hastaneleri | B370: Checkup - genel - lead | C370: 2026-06-23 | D370: Hastane (Kurumsal) | E370: Lead Toplama (Form) | F370: Lead - Check-up/Tarama | G370: 1059.16 | H370: Potansiyel müşteriler (form) | I370: 2 | J370: 7826 | K370: 10134
A371: Doruk Hastaneleri | B371: CBO / Saç Ekimi - lead / soğuk | C371: 2026-07-10 | D371: Hastane (Kurumsal) | E371: Lead Toplama (Form) | F371: Lead - Estetik/Plastik/Saç | G371: 1054.18 | I371: 0 | J371: 4425 | K371: 7306
A372: Doruk Hastaneleri | B372: Checkup - genel - lead | C372: 2026-07-03 | D372: Hastane (Kurumsal) | E372: Lead Toplama (Form) | F372: Lead - Check-up/Tarama | G372: 1053.64 | H372: Potansiyel müşteriler (form) | I372: 2 | J372: 7225 | K372: 9705
A373: Doruk Hastaneleri | B373: Uzman Hekim Başvuru | C373: 2026-07-04 | D373: Hastane (Kurumsal) | E373: Lead Toplama (Form) | F373: Lead - İK/İş Başvurusu | G373: 1053.01 | H373: Potansiyel müşteriler (form) | I373: 1 | J373: 6506 | K373: 7972
A374: Doruk Hastaneleri | B374: CBO / Saç Ekimi - lead / soğuk | C374: 2026-06-26 | D374: Hastane (Kurumsal) | E374: Lead Toplama (Form) | F374: Lead - Estetik/Plastik/Saç | G374: 1048.97 | H374: Potansiyel müşteriler (form) | I374: 2 | J374: 5141 | K374: 7020
A375: Doruk Hastaneleri | B375: ABO / Meme Estetiği / plastik cerrahi / lead | C375: 2026-07-10 | D375: Hastane (Kurumsal) | E375: Lead Toplama (Form) | F375: Lead - Estetik/Plastik/Saç | G375: 1047.38 | H375: Potansiyel müşteriler (form) | I375: 4 | J375: 5807 | K375: 7817
...
